#VRML_SIM R2019a utf8
WorldInfo {
  basicTimeStep 16
}
Viewpoint {
  orientation -0.4649035348079166 0.8584785728831086 0.21651615002970492 0.9652290965787219
  position 1.1570990295830075 0.5605204765520209 1.2172866636872153
}
TexturedBackground {
}
TexturedBackgroundLight {
}
RectangleArena {
}
Robot {
  children [
    DEF BODYSHAPE Shape {
      geometry Box {
        size 0.1 0.1 0.1
      }
    }
    HingeJoint {
      jointParameters HingeJointParameters {
        anchor 0.06 0 0.05
      }
      device [
        RotationalMotor {
        }
      ]
      endPoint DEF WHEEL1 Solid {
        translation 0.06 0 0.05
        children [
          DEF WHEEL Transform {
            rotation 0 0 1 1.5707963220000003
            children [
              Shape {
                appearance Appearance {
                  material Material {
                    diffuseColor 0 1 0
                  }
                }
                geometry Cylinder {
                  height 0.02
                  radius 0.04
                }
              }
            ]
          }
        ]
        boundingObject USE WHEEL
        physics DEF WHEEL_PH Physics {
        }
      }
    }
  ]
  boundingObject USE BODYSHAPE
  physics Physics {
  }
}
WoodenBox {
  translation -0.41912421325119464 0.04999999999999978 -0.3844799190157846
  rotation 0 -1 0 0.0916297857297021
  size 0.1 0.1 0.1
  mass 1
}
